Workbook
Name ARB_Doc_Tracker: #REF!
Name Authentication: #REF!
Name Benefit_Register: #REF!
Name Configuration_Mode: #REF!
Name Database_Type: #REF!
Name Date: [1]Lists!$C$3:$C$62
Name Date1: [2]Lists!$C$3:$C$62
Name Design_Assumptions: #REF!
Name List: #REF!
Name SourcingEngineering: '[3]Project Information'!$B$29
Name SRM_Certificates: #REF!
Name SSL_Policy: #REF!
Name Status: [1]Lists!$A$3:$A$5
Name Status1: [2]Lists!$A$3:$A$5
Name SWDeveloper: '[3]Project Information'!$B$13
Name System_Type: #REF!
Name Task_Table: #REF!
Name VR_Database_Type: #REF!

Sheet Title
A1: VMware Solution
A35: VMware and Customer Confidential

Sheet Change Log
A1: Changes to Program Governanace Asset List
A2: Date | B2: Owner | C2: Change Description
A3: 45692 | B3: John McGillick | C3: Removed Program Governance Asset List tab as the information regarding program governance is located in the Global Delivery Methodology
A4: Changes to REMOVE How to Complete the RTM
A5: Date | B5: Owner | C5: Change Description
A6: 45692 | B6: John McGillick | C6: Updated the tab to reflect the new fields and descriptions within the Requirements, Design Decisions, Design Assumptions, and Design Constraints tabs.
A7: 43930 | B7: John McGillick | C7: Updated description for Impact on the Assumptions tab.
A8: Changes to Handover Checlklist
A9: Date | B9: Owner | C9: Change Description
A10: 45692 | B10: John McGillick | C10: Removed Handover Checklist tab as the information regarding handover is located in the Global Delivery Methodology
A11: Changes to Requirements Tracability
A12: Date | B12: Owner | C12: Change Description
A13: 45692 | B13: John McGillick | C13: Renamed Requirements Tracability tab name to Requirements.
A14: 45692 | B14: John McGillick | C14: Changed Business Requirement / Outcome to Business Requirement / Outcome / Use Case
A15: 45692 | B15: John McGillick | C15: Moved Design Quality column from postion 4 to position 6
A16: 45692 | B16: John McGillick | C16: Moved Business Requirement raised by: Customer Name / Role column from postion 5 to position 4
A17: 45692 | B17: John McGillick | C17: Moved Technical Requirements (Functional or Non Functional) column from position 6 to position 5
A18: 45692 | B18: John McGillick | C18: Changed Requirement Source Date to Date Raised and moved the column from positon 7 to position 8
A19: 45692 | B19: John McGillick | C19: Change Requirement Source (Workshop / Meeting Title) to Source (Workshop / Meeting Title) and moved the column from position 8 to position 9
A20: 45692 | B20: John McGillick | C20: Moved Priority (MoSCoW) column from position 9 to position 7
A21: 45692 | B21: John McGillick | C21: Changed Technical Requirement raised by: Consultant & Customer to Origination (Who Recored It, Who Stated It, Who Owns It) (Customer Name and / or PS Architect)
A22: 45692 | B22: John McGillick | C22: Changed Validated By Customer (Customer Name) to Validated By (Lead Architect and Customer)
A23: 45692 | B23: John McGillick | C23: Changed Validation Status to Status
A24: Changes to Challenges and Outcomes
A25: Date | B25: Owner | C25: Change Description
A26: 45692 | B26: John McGillick | C26: Removed Challenges and Oiutcomes tab because there are better ways to obtain business outcomes through sales/SDE's (e.g., OGSM, OKR, Future State Discovery (FSD), Future State Architecture (FSA), Draft High-Level Designs (SSA / Pre-Sales). Also, business requirements, outcomes, and use cases are in the Requirements tab.
A27: Changes to Design Decisions
A28: Date | B28: Owner | C28: Change Description
A29: 45692 | B29: John McGillick | C29: Added blank column in position 8 to be consistent with the overall cosmetics of the document
A30: 45692 | B30: John McGillick | C30: Changed Decision ID to ID
A31: 45692 | B31: John McGillick | C31: Changed Solution Element to Workstream
A32: 45692 | B32: John McGillick | C32: Changed Alternative Solution to Alernative Solution Considered
A33: 45692 | B33: John McGillick | C33: Changed Business Requirement ID to Related Business Requirement ID(s) and moved the column from postion 10 to position 7
A34: 45692 | B34: John McGillick | C34: Moved Status column from postion 8 to postion 11
A35: 45692 | B35: John McGillick | C35: Removed Compliant column
A36: 45692 | B36: John McGillick | C36: Changed Owner (VMware PS Architect and Customer Technical Lead) to Validated By (Lead Architect and Customer)
A37: 45692 | B37: John McGillick | C37: Added Validatiion Date in column 10
A38: Changes to Design Assumptions
A39: Date | B39: Owner | C39: Change Description
A40: 45692 | B40: John McGillick | C40: Added row 2 (Definition / Validation), blank column in position 8, and changed color scheme to be consistent with the overall cosmetics of the document
...

Sheet REMOVE How To Complete the RTM
A1: Requirements Tab - All columns to be completed by the PS Architect. All assumpotions need to be be validated and sign off by the lead architect and customer.
A2: Definition | K2: Validation
A3: ID | B3: Workstream | C3: Business Requirement / Outcome / Use Case | D3: Business Requirement raised by: Customer Name / Role | E3: Technical Requirements (Functional or Non Functional) | F3: Design Quality | G3: Priority (MoSCoW) | H3: Date Raised | I3: Source (Workshop / Meeting Title) | J3: Origination (Who Recored It, Who Stated It, Who Owns It) (Customer Name and / or PS Architect) | K3: Validated By (Lead Architect and Customer) | L3: Validation Date | M3: Status | N3: Comments
A4: Self Generated ID for future reference. This should be in the format of REQ-XXX-YYY where XXX is the workstream acronym and YYY is a numeric value. See Naming Convention table below. | B4: Cloud Foundation Platform (CFP), Cloud Foundation Network (CFN), Cloud Foundation Security (CFS), Fleet Management Identity Access (FMIA), Monitoring and Alerting Platform (MAP), Logging Platform (LP), Intelligent Network Visibility (INV), Automated Platform (AP), Kubernetes Platform (KP), Cloud Foundation Migration (CFM), Live Site Recovery (LSR) | C4: Indicate the business requirement, outcome, or use case the technical requirement addresses | D4: Provide the name and title of the client that raised the business requirement, outcome, or use case. | E4: Functional Requirements define what a system is supposed to do. (e.g., All activities by all administrators and users should be logged and recorded accordingly. Non Functional - Specifications that describe the system's operation capabilities and constraints such as speed, security, reliability, data integrity (e.g., The system must meet PCI Compliance x.y.z). There can be multiple Technical Requirements to a single Business Requirement | F4: Scalability Performance Availability Maintainability Manageability Extensibility Recoverability Security Cost Manageability Recoverability Performance Security Scalability Cost | G4: Must Have, Should Have, Could Have or Will / Wont Have | H4: Date that the item was first identified in ISO format. Example: 2025-01-01 | I4: Include the workshop, meeting or discussion that this requirement was taken from | J4: Who recorded the requirement, who stated the requirement, who owns the requirement | K4: Provide the name and title of the responsible VMware lead architect **AND** client that approved and validated the item | L4: Date that the item was validated format. Example: 2025-01-01 | M4: Open, Closed, Awaiting Customer Information | N4: List any additional comments related to the validation of the requirement
A6: Design Decisions Tab - All columns to be completed by the PS Architect. All design decisions need to be validated and signed off by the lead architect and customer.
A7: Definition | H7: Validation
A8: ID | B8: Workstream | C8: Design Decision | D8: Design Justification | E8: Design Implication | F8: Alternative Solution Considered | G8: Related Business Requirement ID(s) | H8: Validated By (Lead Architect and Customer) | I8: Validated Date | J8: Status | K8: Comments
A9: Self Generated ID for future reference. This should be in the format of DEC-XXX-YYY where XXX is the workstream acronym and YYY is a numeric value. See Naming Convention table below. | B9: Cloud Foundation Platform (CFP), Cloud Foundation Network (CFN), Cloud Foundation Security (CFS), Fleet Management Identity Access (FMIA), Monitoring and Alerting Platform (MAP), Logging Platform (LP), Intelligent Network Visibility (INV), Automated Platform (AP), Kubernetes Platform (KP), Cloud Foundation Migration (CFM), Live Site Recovery (LSR) | C9: Indicate the design decision that addresses a particular requirement(s) (defined in the Requirements Tab) considering the associated assumption, contraint, and/or risks. | D9: Provide the rationale behind the design decision | E9: Document any downstream implications of the decision. Include factors such as: - Limitations to features and capabilities - Operational changes - Future upgrade concerns | F9: Provide the alternate solution that could address tge requirement (if applicable) | G9: List the business requirement ID(s) that this design decision addresses. A design decision could address mutiple requirements. | H9: Provide the name and title of the responsible VMware lead architect **AND** client that approved and validated the item | I9: Date that the item was validated format. Example: 2025-01-01 | J9: Open, Closed, Awaiting Customer Information | K9: List any additional comments related to the validation of the design decision
A11: Design Assumptions Tab - All columns to be completed by the PS Architect. All design decisions need to be validated and signed off by the lead architect and customer.
A12: Definition | H12: Validation
A13: ID | B13: Workstream | C13: Related Design Decision | D13: Description | E13: Date Raised | F13: Originator (Customer Name and / or PS Architect) | G13: Impact (Assumption not Met) | H13: Validated by (Lead Architect and Customer) | I13: Validation Date | J13: Status | K13: Comments
A14: Self Generated ID for future reference. This should be in the format of ASM-XXX-YYY where XXX is the workstream acronym and YYY is a numeric value. See Naming Convention table below. | B14: Cloud Foundation Platform (CFP), Cloud Foundation Network (CFN), Cloud Foundation Security (CFS), Fleet Management Identity Access (FMIA), Monitoring and Alerting Platform (MAP), Logging Platform (LP), Intelligent Network Visibility (INV), Automated Platform (AP), Kubernetes Platform (KP), Cloud Foundation Migration (CFM), Live Site Recovery (LSR) | C14: Indicate the design decision that this assumption is realted to | D14: Indicate what can is assumed to be true but has not been validated that could impact a design decision. | E14: Date that the item was first identified in ISO format. Example: 2025-01-01 | F14: Provide the name and title of the responsible VMware by Broadcom architect or the customer who originated this assumption | G14: The Impact reveals what is likely to happen if the assumption turns out not to be true. It is an explanation of additional design considerations and/or implementation work that would surface when it is found to be invalid. | H14: Provide the name and title of the responsible VMware lead architect **AND** client that approved and validated the item | I14: Date that the item was validated format. Example: 2025-01-01 | J14: Open, Closed, Awaiting Customer Information | K14: List any additional comments related to the validation of the assumption
A16: Design Constraints Tab - All columns to be completed by the PS Architect. All design decisions need to be validated and signed off by the lead architect and customer.
A17: Definition | G17: Validation
A18: ID | B18: Workstream | C18: Related Design Decision | D18: Description | E18: Date Raised | F18: Originator (Customer Name and / or PS Architect) | G18: Validated by (Lead Architect and Customer) | H18: Validated Date | I18: Status | J18: Comments
A19: Self Generated ID for future reference. This should be in the format of CON-XXX-YYY where XXX is the workstream acronym and YYY is a numeric value. See Naming Convention table below. | B19: Cloud Foundation Platform (CFP), Cloud Foundation Network (CFN), Cloud Foundation Security (CFS), Fleet Management Identity Access (FMIA), Monitoring and Alerting Platform (MAP), Logging Platform (LP), Intelligent Network Visibility (INV), Automated Platform (AP), Kubernetes Platform (KP), Cloud Foundation Migration (CFM), Live Site Recovery (LSR) | C19: Indicate the design decision that this constraint is realted to | D19: Indicate the limitation imposed that affects the related design decision | E19: Date that the item was first identified in ISO format. Example: 2025-01-01 | F19: Provide the name and title of the responsible VMware by Broadcom architect or the customer who originated this assumption | G19: Provide the name and title of the responsible VMware lead architect **AND** client that approved and validated the item | H19: Date that the item was validated format. Example: 2025-01-01 | I19: Open, Closed, Awaiting Customer Information | J19: List any additional comments related to the validation of the assumption
A21: RAID items related to the design can be logged in the Design Issues and Design Risks tabs. However, you may choose to log them in the central project RAID log managed by the PM. If you are logging RAID items within this document and a line item that will affect the project or program timelines, delivery dates, or costs should be logged in the central RAID log.
A23: Design Issues Register
A24: Definition
A25: ID | B25: Workstream | C25: Description | D25: Criticality | E25: Status | F25: Impact (Low, Medium, High) | G25: Issue Mitigation | H25: Originator (Customer Name and / or PS Architect) | I25: Owner | J25: Date Identified | K25: Planned Resolution Date | L25: Actual Resolution Date | M25: Issue Management Updates (including dates)
A26: Self Generated ID for future reference. This should be in the format of DIR-XXX-YYY where XXX is the workstream acronym and YYY is a numeric value. See Naming Convention table below. | B26: Cloud Foundation Platform (CFP), Cloud Foundation Network (CFN), Cloud Foundation Security (CFS), Fleet Management Identity Access (FMIA), Monitoring and Alerting Platform (MAP), Logging Platform (LP), Intelligent Network Visibility (INV), Automated Platform (AP), Kubernetes Platform (KP), Cloud Foundation Migration (CFM), Live Site Recovery (LSR) | C26: Describe the issue | D26: Describe the criticality of the issue. Since a design issue is confirmed problem that is happening now and requires immediate attention there is no scale to choose from. | E26: Active Resolved | F26: Low Medium High | G26: Describe the proactive strategy to reduce the likelihood or eliminate the issue. | H26: Provide the name and title of the responsible VMware by Broadcom architect or the customer who originated this issue | I26: Provide the owner who is responsible for the Status, Issue Mitigation, and the overall management of the issue until it is resolved. | J26: Date that the issue was first identified in ISO format. Example: 2025-01-01 | K26: Date that the issue is plannned to be resolved in ISO format. Example: 2025-01-01 | L26: Date that the risk was resolved in ISO format. Example: 2025-01-01 | M26: A running log of the updates to the issue until it is resolved
A28: Design Risks Register
A29: Definition
A30: ID | B30: Workstream | C30: Description (Including Trigger) | D30: Impact Description | E30: Probability (Very Low - Very High) | F30: Impact (Very Low - Very High) | G30: Risk Score | H30: Status | I30: Risk Reponse Strategy | J30: Originator (Customer Name and / or PS Architect) | K30: Owner | L30: Date Identified | M30: Planned Resolution Date | N30: Actual Resolution Date | O30: Risk Management Updates (including dates) | P30: Related Issue ID (if applicable)
A31: Self Generated ID for future reference. This should be in the format of DRR-XXX-YYY where XXX is the workstream acronym and YYY is a numeric value. See Naming Convention table below. | B31: Cloud Foundation Platform (CFP), Cloud Foundation Network (CFN), Cloud Foundation Security (CFS), Fleet Management Identity Access (FMIA), Monitoring and Alerting Platform (MAP), Logging Platform (LP), Intelligent Network Visibility (INV), Automated Platform (AP), Kubernetes Platform (KP), Cloud Foundation Migration (CFM), Live Site Recovery (LSR) | C31: Describe the risk and include what trigged the risk | D31: Describe the risk's impact of the design of the solution | E31: Very Low Low Medium High Very High | F31: Very Low Low Medium High Very High | G31: By entering the Probability and Impact, a Risk Score will be computed automatically. The value will be from 1 to 5. | H31: Active Resolved | I31: Tolerate Terminate Treat Transfer | J31: Provide the name and title of the responsible VMware by Broadcom architect or the customer who originated this risk | K31: Provide the owner who is responsible for the Status, Risk Response Strategy, and the overall management of the risk until it is resolved | L31: Date that the risk was first identified in ISO format. Example: 2025-01-01 | M31: Date that the risk is plannned to be resolved in ISO format. Example: 2025-01-01 | N31: Date that the risk was resolved in ISO format. Example: 2025-01-01 | O31: A running log of the updates to the risk until it is resolved | P31: Indicate the Issue ID that this risk is realted to (if applicable).
A33: Naming Convention Table
A35: VCF 5.x | B35: Description | C35: VCF 9.x | D35: Description
A37: VCF | B37: Cloud Foundation Platform | C37: CFP | D37: Cloud Foundation Platform
A38: NSX | B38: Cloud Foundation Networking | C38: CFN | D38: Cloud Foundation Network
A39: VCFS | B39: Cloud Foundation Security | C39: CFS | D39: Cloud Foundation Security
A40: ASLAM | B40: Aria Suite Lifecycle and Access Management | C40: FMIA | D40: Fleet Management Identity Access
A41: AOPS | B41: Aria Operations | C41: MAP | D41: Monitoring and Alerting Platform
A42: AOPS4L | B42: Aria Operations for Logs | C42: LP | D42: Logging Platform
A43: AOPS4N | B43: Aria Operations for Networks | C43: INV | D43: Intelligent Network Visibility
A44: AA | B44: Aria Automation | C44: AP | D44: Automated Platform
A45: TKGS | B45: Tanzu Kubernetes Grid Service | C45: KP | D45: Kubernetes Platform
A46: HCX | B46: Hybrid Cloud Extension | C46: CFM | D46: Cloud Foundation Migration
A47: LSR | B47: Live Site Recovery | C47: LSR | D47: Live Site Recovery

Sheet Risk User Guide
A4: Design Risks
A5: This worksheet contains all design risks. The risk score is automatically calculated via the recorded Probability and Impact cells using the formula below.
A7: Risk Level = (2*Probability + 3*Impact) / 5 | I7: Risk Levels
A8: Probability | B8: Very high | C8: 2.6 | D8: 3.2 | E8: 3.8 | F8: 4.4 | G8: 5 | I8: Very high | J8: 5
B9: High | C9: 2 | D9: 2.8 | E9: 3.4 | F9: 4 | G9: 4.6 | I9: High | J9: 4
B10: Medium | C10: 1.8 | D10: 2.4 | E10: 3 | F10: 3.6 | G10: 4.2 | I10: Medium | J10: 3
B11: Low | C11: 1.4 | D11: 2 | E11: 2.6 | F11: 3.2 | G11: 3.8 | I11: Low | J11: 2
B12: Very low | C12: 1 | D12: 1.6 | E12: 2.2 | F12: 2.8 | G12: 3.4 | I12: Very low | J12: 1
C13: Very low | D13: Low | E13: Medium | F13: High | G13: Very high
B14: Impact
A16: Definitions for qualitative assessment:
B18: Probability | L18: Weighting | P18: Definition | Q18: Business context
A19: Very low | B19: Unlikely to occur - less than 5% | L19: 1 | P19: Highly unlikely, will occur only in very exceptional circumstances. Very confident risk can be managed at this level. Controls operate normally. | Q19: By awarding this level we are asserting that this risk has not previously occurred or that we are confident it cannot occur with the controls / business processes / procedures in place.
A20: Low | B20: Low, but not impossible - between 5% and 20% | L20: 2 | P20: Not expected, this event has a small chance of occurring at some times | Q20: By awarding this level this risk has not previously happened or on a extremely infrequent basis (less than 1 per year) and is not expected to occur within 6 months if no remediation or fix is implemented.
A21: Medium | B21: Fairly likely to happen - between 20% and 50% | L21: 3 | P21: This event is likely to occur at sometimes even if controls operate normally. Confident risk can be managed at this level. | Q21: By awarding this level the event has occurred previously but not frequently. At this level the assertion would be that with no mitigation or fix the event is not expected to materialise (3-6 months)
A22: High | B22: More likely to happen than not - between 50% and 70% | L22: 4 | P22: This event is likely to occur in most circumstances. Requires additional mitigation / contingency. Little confidence risk can be managed at this level. | Q22: By awarding this level, there is evidence that this event has occurred previously (frequently) or is likely to occur in a short timeframe (months) without adequate remediation or fix.
A23: Very high | B23: Extremely likely to happen – more than 70% | L23: 5 | P23: Very likely. This event may be imminent or strong indications that this will occur in the future. Not confident risk can be managed at this level and contingency is required. | Q23: A regular occurrence, circumstances found frequently. To award this likelihood level we are asserting that this risk is happening or is likely to happen within almost immediate proximity
B25: Impact | L25: Weighting
A26: Very low | B26: Negligible impact on the schedule, cost and/or quality of project/deliverables. Can be managed by project team through to resolution. Cost: Negligible impact on project budget: cost 0 to 3% Schedule: Likely to cause a delay to the schedule but any products concerned will still be ready in time for the relevant Milestone Review. Quality: no impact on Milestone reviews | L26: 1
A27: Low | B27: Minor delays/impact to schedule, cost and/or quality of project/deliverables. Managed by the project team through to resolution. Cost: Small increase on project budget: cost 3% to 10% Schedule: Likely to cause a product to be delayed to the extent that it will not be ready in time for the relevant Milestone Review but the Milestone Review will not need to be delayed Quality: No impact on Milestone reviews | L27: 2
A28: Medium | B28: Major delays/impact to schedule cost and/or quality of project /deliverables. May affect other projects throughout the Programme. Managed by the Project Manager through to resolution or may require escalation to next level of management to intervene and resolve. Cost: Significant increase on project budget: cost 10% to 20% Schedule: Likely to delay a Milestone Review by less than 10% of project duration but have no knock-on effect on other Milestone Reviews Quality: VMware failure of milestone gate | L28: 3
A29: High | B29: Delay to any key or interim project milestone. Mandatory escalation to next level of management to own and resolve. Cost: Large increase on project budget: cost 20% to 30% Schedule: Either, likely to delay a Milestone Review by more than 10% of project duration but have no knock-on affect on other Milestone Reviews, or, likely to delay a Milestone Review by less than 10% of project duration and have a knock-on affect on another Milestone Review Quality: Client rejection of interim milestone | L29: 4
A30: Very high | B30: Key contracted deliverable is impacted. Mandatory escalation to next level of management to own and resolve. Cost: Major increase on project budget: cost greater than 30% Schedule: Likely to delay a Milestone Review by more than 10% of project duration and have a knock-on affect on another Milestone Review Quality: Client rejection of bundle/key milestone | L30: 5
B32: Risk Response Strategy
A33: Terminate (avoid / eliminate) | B33: Some risks will be treatable, or containable to acceptable levels by terminating the activity. A level of risk that should be avoided and if possible should be eliminated.
A34: Treat (control/reduce) | B34: This refers to the level of cost-effective (corrective) controls put in place to manage the risk to an acceptable level. The majority of risks will be managed in this way.
A35: Transfer (insurance/contact) | B35: Where the decision is taken to transfer the risk to a third party usually by means of insurance or contractual transfer such as paying a third party to take the risk.
A36: Tolerate (accept /retain) | B36: The risk here is considered acceptable to the client or the ability to do anything about this risk is limted, or the cost of taking action may be disproportionate to the potential benefit gained. Should be monitored and re-evaluated in the future.A36:K36

Sheet Requirements
A1: Business / Technical Requirements
A2: Definition | L2: Validation
A3: ID | B3: Workstream | C3: Business Requirement / Outcome / Use Case | D3: Business Requirement raised by: Customer Name / Role | E3: Technical Requirements (Functional or Non Functional) | F3: Design Quality | G3: Priority (MoSCoW) | H3: Date Raised | I3: Source (Workshop / Meeting Title) | J3: Origination (Who Recored It, Who Stated It, Who Owns It) (Customer Name and / or PS Architect) | L3: Validated By (Lead Architect and Customer) | M3: Validation Date | N3: Status | O3: Comments

Sheet Design Decisions
A1: Design Decisions
A2: Definition
A3: ID | B3: Workstream | C3: Design Decision | D3: Design Justification | E3: Design Implication | F3: Alternative Solution Considered | G3: Related Business Requirement ID(s) | I3: Validated By (Lead Architect and Customer) | J3: Validated Date | K3: Status | L3: Comments

Sheet Design Assumptions
A1: Design Assumptions
A2: Definition | I2: Validation
A3: ID | B3: Workstream | C3: Related Design Decision ID(s) | D3: Description | E3: Date Raised | F3: Originator (Customer Name and / or PS Architect) | G3: Impact (Assumption not Met) | I3: Validated by (Lead Architect and Customer) | J3: Validation Date | K3: Status | L3: Comments

Sheet Design Constraints
A1: Design Constraints
A2: Definition | H2: Validation
A3: ID | B3: Workstream | C3: Related Design Decision | D3: Description | E3: Date Raised | F3: Originator (Customer Name and / or PS Architect) | H3: Validated by (Lead Architect and Customer) | I3: Validated Date | J3: Status | K3: Comments

Sheet Design Issues
A1: Design Issues Register
A2: Definition
A3: ID | B3: Workstream | C3: Description | D3: Criticality | E3: Status | F3: Impact (Low, Medium, High) | G3: Issue Mitigation | H3: Originator (Customer Name and / or PS Architect) | I3: Owner | J3: Date Identified | K3: Planned Resolution Date | L3: Actual Resolution Date | M3: Issue Management Updates (including dates)

Sheet Design Risks
A1: Design Risks Register
A2: Definition
A3: ID | B3: Workstream | C3: Description (Including Trigger) | D3: Impact Description | E3: Probability (Very Low - Very High) | F3: Impact (Very Low - Very High) | G3: Risk Score | H3: Status | I3: Risk Reponse Strategy | J3: Originator (Customer Name and / or PS Architect) | K3: Owner | L3: Date Identified | M3: Planned Resolution Date | N3: Actual Resolution Date | O3: Risk Management Updates (including dates) | P3: Related Issue ID (if applicable)
E4: Very Low | F4: Low | G4: =(2*VLOOKUP(E4,'Risk User Guide'!$I$8:$J$12,2,FALSE)+3*VLOOKUP(F4,'Risk User Guide'!$I$8:$J$12,2,FALSE))/5 -> 1.6
G5: =(2*VLOOKUP(E5,'Risk User Guide'!$I$8:$J$12,2,FALSE)+3*VLOOKUP(F5,'Risk User Guide'!$I$8:$J$12,2,FALSE))/5 -> #N/A
G6: =(2*VLOOKUP(E6,'Risk User Guide'!$I$8:$J$12,2,FALSE)+3*VLOOKUP(F6,'Risk User Guide'!$I$8:$J$12,2,FALSE))/5 -> #N/A
G7: =(2*VLOOKUP(E7,'Risk User Guide'!$I$8:$J$12,2,FALSE)+3*VLOOKUP(F7,'Risk User Guide'!$I$8:$J$12,2,FALSE))/5 -> #N/A
G8: =(2*VLOOKUP(E8,'Risk User Guide'!$I$8:$J$12,2,FALSE)+3*VLOOKUP(F8,'Risk User Guide'!$I$8:$J$12,2,FALSE))/5 -> #N/A
G9: =(2*VLOOKUP(E9,'Risk User Guide'!$I$8:$J$12,2,FALSE)+3*VLOOKUP(F9,'Risk User Guide'!$I$8:$J$12,2,FALSE))/5 -> #N/A
G10: =(2*VLOOKUP(E10,'Risk User Guide'!$I$8:$J$12,2,FALSE)+3*VLOOKUP(F10,'Risk User Guide'!$I$8:$J$12,2,FALSE))/5 -> #N/A
G11: =(2*VLOOKUP(E11,'Risk User Guide'!$I$8:$J$12,2,FALSE)+3*VLOOKUP(F11,'Risk User Guide'!$I$8:$J$12,2,FALSE))/5 -> #N/A
G12: =(2*VLOOKUP(E12,'Risk User Guide'!$I$8:$J$12,2,FALSE)+3*VLOOKUP(F12,'Risk User Guide'!$I$8:$J$12,2,FALSE))/5 -> #N/A
G13: =(2*VLOOKUP(E13,'Risk User Guide'!$I$8:$J$12,2,FALSE)+3*VLOOKUP(F13,'Risk User Guide'!$I$8:$J$12,2,FALSE))/5 -> #N/A
G14: =(2*VLOOKUP(E14,'Risk User Guide'!$I$8:$J$12,2,FALSE)+3*VLOOKUP(F14,'Risk User Guide'!$I$8:$J$12,2,FALSE))/5 -> #N/A
G15: =(2*VLOOKUP(E15,'Risk User Guide'!$I$8:$J$12,2,FALSE)+3*VLOOKUP(F15,'Risk User Guide'!$I$8:$J$12,2,FALSE))/5 -> #N/A
G16: =(2*VLOOKUP(E16,'Risk User Guide'!$I$8:$J$12,2,FALSE)+3*VLOOKUP(F16,'Risk User Guide'!$I$8:$J$12,2,FALSE))/5 -> #N/A
... G80: =(2*VLOOKUP(E80,'Risk User Guide'!$I$8:$J$12,2,FALSE)+3*VLOOKUP(F80,'Risk User Guide'!$I$8:$J$12,2,FALSE))/5 -> #N/A

Sheet Drop Down Table Data
A1: Design Quality | B1: MoSCoW | C1: Req Validation Status | D1: Design Decision Status | E1: Assumption | F1: Constraint | G1: Risk Probability | H1: Risk Impact | I1: Risk Status | J1: Risk Response Strategy | K1: Issue Status | L1: Issue Impact
A2: Scalability | B2: Must Have | C2: Open | D2: Open | E2: Open | F2: Open | G2: Very Low | H2: Very Low | I2: Active | J2: Tolerate | K2: Active | L2: Low
A3: Performance | B3: Should Have | C3: Closed | D3: Closed | E3: Closed | F3: Closed | G3: Low | H3: Low | I3: Resolved | J3: Terminate | K3: Resolved | L3: Medium
A4: Availability | B4: Could Have | C4: Awaiting Customer Information | D4: Awaiting Customer Information | E4: Partial | F4: Partial | G4: Medium | H4: Medium | J4: Treat | L4: High
A5: Maintainability | B5: Won't Have | G5: High | H5: High | J5: Transfer
A6: Manageability | G6: Very High | H6: Very High
A7: Extensibility
A8: Recoverability
A9: Security
A10: Cost
H13: Risk Response Strategy
G14: Terminate (avoid / eliminate) | H14: Some risks will be treatable, or containable to acceptable levels by terminating the activity. A level of risk that should be avoided and if possible should be eliminated.
G15: Treat (control/reduce) | H15: This refers to the level of cost-effective (corrective) controls put in place to manage the risk to an acceptable level. The majority of risks will be managed in this way.
G16: Transfer (insurance/contact) | H16: Where the decision is taken to transfer the risk to a third party usually by means of insurance or contractual transfer such as paying a third party to take the risk.
G17: Tolerate (accept /retain) | H17: The risk here is considered acceptable to the client or the ability to do anything about this risk is limted, or the cost of taking action may be disproportionate to the potential benefit gained. Should be monitored and re-evaluated in the future.A36:K36
A18: Scalability
A19: Performance
A20: Availability
A21: Maintainability
A22: Manageability
A23: Extensibility
A24: Recoverability
A25: Security

Sheet Workbook Setup
A1: Validation Status
A2: Passed
A3: Failed
A4: Blocked
A5: Retest
A7: Moscow
A8: Must Have
A9: Should Have
A10: Could Have
A11: Won't Have
